Workbook

Sheet README
A1: GLOBAL PROCUREMENT ANALYTICS — PORTFOLIO DATASET V2
A4: Dataset purpose | B4: Foundation dataset for SQL, Power BI, data modeling, and procurement analytics portfolio
A5: Business context | B5: Synthetic multinational enterprise; all names and records are fictional
A6: Currency | B6: USD
A7: PO period | B7: 2024-01-01 to 2026-07-31
A8: Calendar coverage | B8: 2024-01-01 to 2026-12-31
A9: Transaction grain | B9: One row in Fact_PO_Detail = one purchase order line
A10: Transaction rows | B10: 3,000 PO lines across 1,250 purchase orders
A11: Business rule | B11: One PO belongs to one vendor; a PO can contain 1-3 lines
A12: Primary KPI | B12: Spend, Cost Saving, Saving %, On-Time Delivery, Defect Rate, Invoice Outstanding
A13: Cost Saving definition | B13: (Baseline Unit Price - Negotiated Unit Price) × Ordered Quantity
A14: Important | B14: Use raw price fields to calculate KPIs in SQL; calculated Excel columns are included for checking
A18: Sequence | B18: Table | C18: Primary key | D18: Main foreign keys | E18: Grain | F18: Purpose
A19: 1 | B19: Dim_Date | C19: DateKey | D19: — | E19: One calendar day | F19: Time intelligence
A20: 2 | B20: Dim_Department | C20: DepartmentID | D20: — | E20: One department | F20: Spend ownership
A21: 3 | B21: Dim_Category | C21: CategoryID | D21: — | E21: One category | F21: Category hierarchy
A22: 4 | B22: Dim_Vendor | C22: VendorID | D22: PrimaryCategoryID | E22: One supplier | F22: Supplier attributes
A23: 5 | B23: Dim_Product | C23: ProductID | D23: CategoryID | E23: One product/service | F23: Product master
A24: 6 | B24: Bridge_VendorProduct | C24: VendorProductID | D24: VendorID, ProductID | E24: Eligible vendor-product pair | F24: Many-to-many eligibility
A25: 7 | B25: Fact_PO_Header | C25: PO_ID | D25: DepartmentID, VendorID | E25: One purchase order | F25: PO-level attributes
A26: 8 | B26: Fact_PO_Detail | C26: PO_Line_ID | D26: PO_ID, ProductID, VendorID, QuotationID | E26: One PO line | F26: Primary spend fact
A27: 9 | B27: Fact_Quotation | C27: QuotationID | D27: PO_Line_ID, VendorID | E27: One accepted quotation | F27: Negotiation analysis
A28: 10 | B28: Fact_Delivery | C28: DeliveryID | D28: PO_Line_ID | E28: One PO-line delivery | F28: OTD and quality
A29: 11 | B29: Fact_Invoice | C29: InvoiceID | D29: PO_ID | E29: One PO invoice | F29: Invoice matching
A30: 12 | B30: Fact_Payment | C30: PaymentID | D30: InvoiceID | E30: One invoice payment record | F30: Outstanding and payment performance

Sheet Dim_Date
A1: DateKey | B1: FullDate | C1: Year | D1: Quarter | E1: MonthName | F1: MonthNumber | G1: DayName | H1: IsBusinessDay
A2: 20240101 | B2: 45292 | C2: 2024 | D2: 1 | E2: Jan | F2: 1 | G2: Mon | H2: 1
A3: 20240102 | B3: 45293 | C3: 2024 | D3: 1 | E3: Jan | F3: 1 | G3: Tue | H3: 1
A4: 20240103 | B4: 45294 | C4: 2024 | D4: 1 | E4: Jan | F4: 1 | G4: Wed | H4: 1
A5: 20240104 | B5: 45295 | C5: 2024 | D5: 1 | E5: Jan | F5: 1 | G5: Thu | H5: 1
A6: 20240105 | B6: 45296 | C6: 2024 | D6: 1 | E6: Jan | F6: 1 | G6: Fri | H6: 1
A7: 20240106 | B7: 45297 | C7: 2024 | D7: 1 | E7: Jan | F7: 1 | G7: Sat | H7: 0
A8: 20240107 | B8: 45298 | C8: 2024 | D8: 1 | E8: Jan | F8: 1 | G8: Sun | H8: 0
A9: 20240108 | B9: 45299 | C9: 2024 | D9: 1 | E9: Jan | F9: 1 | G9: Mon | H9: 1
A10: 20240109 | B10: 45300 | C10: 2024 | D10: 1 | E10: Jan | F10: 1 | G10: Tue | H10: 1
A11: 20240110 | B11: 45301 | C11: 2024 | D11: 1 | E11: Jan | F11: 1 | G11: Wed | H11: 1
A12: 20240111 | B12: 45302 | C12: 2024 | D12: 1 | E12: Jan | F12: 1 | G12: Thu | H12: 1
A13: 20240112 | B13: 45303 | C13: 2024 | D13: 1 | E13: Jan | F13: 1 | G13: Fri | H13: 1
... A1097: 20261231 | B1097: 46387 | C1097: 2026 | D1097: 4 | E1097: Dec | F1097: 12 | G1097: Thu | H1097: 1

Sheet Dim_Department
A1: DepartmentID | B1: DepartmentName | C1: BusinessUnit | D1: Region | E1: CostCenter
A2: D001 | B2: Information Technology | C2: Corporate Services | D2: North America | E2: CC-1001
A3: D002 | B3: Operations | C3: Core Operations | D3: North America | E3: CC-2001
A4: D003 | B4: Engineering | C4: Core Operations | D4: Europe | E4: CC-2101
A5: D004 | B5: Finance | C5: Corporate Services | D5: Europe | E5: CC-1101
A6: D005 | B6: Human Resources | C6: Corporate Services | D6: Asia Pacific | E6: CC-1201
A7: D006 | B7: Sales | C7: Commercial | D7: North America | E7: CC-3001
A8: D007 | B8: Marketing | C8: Commercial | D8: Europe | E8: CC-3101
A9: D008 | B9: Customer Support | C9: Commercial | D9: Asia Pacific | E9: CC-3201
A10: D009 | B10: Facilities | C10: Corporate Services | D10: Asia Pacific | E10: CC-1301
A11: D010 | B11: Research & Development | C11: Innovation | D11: Europe | E11: CC-4001

Sheet Dim_Vendor
A1: VendorID | B1: VendorName | C1: Country | D1: City | E1: PrimaryCategoryID | F1: Rating | G1: LeadTimeDays | H1: PaymentTerm | I1: Status | J1: RiskTier
A2: V001 | B2: Van Dijk Industrial Solutions | C2: Netherlands | D2: Amsterdam | E2: CAT01 | F2: 4.06 | G2: 30 | H2: Net 30 | I2: Active | J2: RISK-HIGH
A3: V002 | B3: Maple Ridge Procurement | C3: Canada | D3: Toronto | E3: CAT02 | F3: 4.71 | G3: 16 | H3: Net 30 | I3: Active | J3: RISK-MED
A4: V003 | B4: Crownbridge Engineering | C4: United Kingdom | D4: London | E4: CAT03 | F4: 3.65 | G4: 19 | H4: Net 45 | I4: Active | J4: RISK-MED
A5: V004 | B5: Nordholm Technologies | C5: Sweden | D5: Stockholm | E5: CAT04 | F5: 4.47 | G5: 31 | H5: Net 60 | I5: On Hold | J5: RISK-HIGH
A6: V005 | B6: Sakura Field Partners | C6: Japan | D6: Tokyo | E6: CAT05 | F6: 3.64 | G6: 37 | H6: Net 60 | I6: Active | J6: RISK-HIGH
A7: V006 | B7: Bharat Vertex Solutions | C7: India | D7: Bengaluru | E7: CAT06 | F7: 4.11 | G7: 25 | H7: Net 45 | I7: Active | J7: RISK-LOW
A8: V007 | B8: AlpenCore Systems | C8: Switzerland | D8: Zurich | E8: CAT07 | F8: 4.41 | G8: 25 | H8: Net 45 | I8: Active | J8: RISK-MED
A9: V008 | B9: Southern Cross Technologies | C9: Australia | D9: Sydney | E9: CAT08 | F9: 4.66 | G9: 18 | H9: Net 60 | I9: Active | J9: RISK-HIGH
A10: V009 | B10: Rheinwerk Industrial | C10: Germany | D10: Munich | E10: CAT09 | F10: 4.04 | G10: 11 | H10: Net 30 | I10: Active | J10: RISK-MED
A11: V010 | B11: Thamesgate Supply | C11: United Kingdom | D11: London | E11: CAT10 | F11: 4.43 | G11: 11 | H11: Net 30 | I11: Active | J11: RISK-MED
A12: V011 | B12: Shinsei Industrial Group | C12: Japan | D12: Tokyo | E12: CAT11 | F12: 4.13 | G12: 45 | H12: Net 45 | I12: Active | J12: RISK-MED
A13: V012 | B13: Deccan Lumina Solutions | C13: India | D13: Bengaluru | E13: CAT12 | F13: 4.79 | G13: 29 | H13: Net 30 | I13: Active | J13: RISK-MED
... A61: V060 | B61: Coral Coast Supply | C61: Australia | D61: Sydney | E61: CAT12 | F61: 4.54 | G61: 36 | H61: Net 60 | I61: Active | J61: RISK-HIGH

Sheet Dim_Product
A1: ProductID | B1: ProductName | C1: CategoryID | D1: CategoryGroup | E1: Subcategory | F1: UnitOfMeasure | G1: ReferencePrice | H1: WarrantyMonths | I1: Status
A2: P0001 | B2: Laptop 01-001 | C2: CAT01 | D2: Computing | E2: Laptop | F2: Unit | G2: 1864.59 | H2: 24 | I2: Active
A3: P0002 | B3: Desktop 01-002 | C3: CAT02 | D3: Computing | E3: Desktop | F3: Unit | G3: 1481.1 | H3: 12 | I3: Active
A4: P0003 | B4: Monitor 01-003 | C4: CAT03 | D4: IT Equipment | E4: Monitor | F4: Unit | G4: 507.98 | H4: 36 | I4: Active
A5: P0004 | B5: Network Equipment 01-004 | C5: CAT04 | D5: IT Equipment | E5: Network Equipment | F5: Unit | G5: 1728.18 | H5: 12 | I5: Active
A6: P0005 | B6: Business Software 01-005 | C6: CAT05 | D6: Software | E6: Business Software | F6: License | G6: 524.4 | H6: 24 | I6: Active
A7: P0006 | B7: Office Supplies 01-006 | C7: CAT06 | D7: Office | E7: Office Supplies | F7: Pack | G7: 62.81 | H7: 24 | I7: Active
A8: P0007 | B8: Furniture 01-007 | C8: CAT07 | D8: Facilities | E8: Furniture | F8: Unit | G8: 1065.78 | H8: 24 | I8: Active
A9: P0008 | B9: Maintenance Service 01-008 | C9: CAT08 | D9: Facilities | E9: Maintenance Service | F9: Service | G9: 6982.07 | H9: 36 | I9: Active
A10: P0009 | B10: Consulting 01-009 | C10: CAT09 | D10: Professional Services | E10: Consulting | F10: Day | G10: 895.54 | H10: 24 | I10: Active
A11: P0010 | B11: Media & Creative 01-010 | C11: CAT10 | D11: Marketing | E11: Media & Creative | F11: Service | G11: 753.15 | H11: 36 | I11: Active
A12: P0011 | B12: Mobile Device 01-011 | C12: CAT11 | D12: Telecom | E12: Mobile Device | F12: Unit | G12: 519.58 | H12: 36 | I12: Active
A13: P0012 | B13: Freight Service 01-012 | C13: CAT12 | D13: Logistics | E13: Freight Service | F13: Shipment | G13: 3245.12 | H13: 36 | I13: Active
... A121: P0120 | B121: Freight Service 10-120 | C121: CAT12 | D121: Logistics | E121: Freight Service | F121: Shipment | G121: 1467.58 | H121: 36 | I121: Active

Sheet Bridge_VendorProduct
A1: VendorProductID | B1: VendorID | C1: ProductID | D1: ContractedUnitPrice | E1: EligibilityStatus | F1: EffectiveFrom | G1: EffectiveTo
A2: VP00001 | B2: V001 | C2: P0001 | D2: 1732.37 | E2: Approved | F2: 45292 | G2: 46387
A3: VP00002 | B3: V025 | C3: P0001 | D3: 1935.73 | E3: Approved | F3: 45292 | G3: 46387
A4: VP00003 | B4: V037 | C4: P0001 | D4: 1838.69 | E4: Preferred | F4: 45292 | G4: 46387
A5: VP00004 | B5: V049 | C5: P0001 | D5: 1913.61 | E5: Approved | F5: 45292 | G5: 46387
A6: VP00005 | B6: V002 | C6: P0002 | D6: 1513.95 | E6: Approved | F6: 45292 | G6: 46387
A7: VP00006 | B7: V014 | C7: P0002 | D7: 1545.03 | E7: Preferred | F7: 45292 | G7: 46387
A8: VP00007 | B8: V026 | C8: P0002 | D8: 1469.66 | E8: Approved | F8: 45292 | G8: 46387
A9: VP00008 | B9: V038 | C9: P0002 | D9: 1517.28 | E9: Approved | F9: 45292 | G9: 46387
A10: VP00009 | B10: V003 | C10: P0003 | D10: 519.67 | E10: Approved | F10: 45292 | G10: 46387
A11: VP00010 | B11: V015 | C11: P0003 | D11: 486.25 | E11: Preferred | F11: 45292 | G11: 46387
A12: VP00011 | B12: V027 | C12: P0003 | D12: 474.91 | E12: Preferred | F12: 45292 | G12: 46387
A13: VP00012 | B13: V039 | C13: P0003 | D13: 518.94 | E13: Approved | F13: 45292 | G13: 46387
... A471: VP00470 | B471: V048 | C471: P0120 | D471: 1501.42 | E471: Preferred | F471: 45292 | G471: 46387

Sheet Fact_PO_Header
A1: PO_ID | B1: PODate | C1: DepartmentID | D1: VendorID | E1: BuyerID | F1: SourcingMethod | G1: POStatus | H1: PurchaseReason | I1: Currency
A2: PO000001 | B2: 45313 | C2: D004 | D2: V010 | E2: BUY002 | F2: Catalog | G2: Closed | H2: Growth | I2: USD
A3: PO000002 | B3: 45307 | C3: D004 | D3: V039 | E3: BUY002 | F3: Catalog | G3: Closed | H3: Growth | I3: USD
A4: PO000003 | B4: 45321 | C4: D004 | D4: V041 | E4: BUY002 | F4: Catalog | G4: Closed | H4: Growth | I4: USD
A5: PO000004 | B5: 45327 | C5: D005 | D5: V025 | E5: BUY012 | F5: Framework Call-off | G5: Closed | H5: Growth | I5: USD
A6: PO000005 | B6: 45308 | C6: D005 | D6: V048 | E6: BUY012 | F6: Framework Call-off | G6: Closed | H6: Growth | I6: USD
A7: PO000006 | B7: 45300 | C7: D001 | D7: V040 | E7: BUY010 | F7: RFQ | G7: Closed | H7: Compliance | I7: USD
A8: PO000007 | B8: 45371 | C8: D001 | D8: V049 | E8: BUY010 | F8: RFQ | G8: Closed | H8: Compliance | I8: USD
A9: PO000008 | B9: 45327 | C9: D009 | D9: V009 | E9: BUY002 | F9: RFQ | G9: Closed | H9: Compliance | I9: USD
A10: PO000009 | B10: 45341 | C10: D009 | D10: V034 | E10: BUY002 | F10: RFQ | G10: Closed | H10: Compliance | I10: USD
A11: PO000010 | B11: 45323 | C11: D001 | D11: V006 | E11: BUY008 | F11: Framework Call-off | G11: Closed | H11: Growth | I11: USD
A12: PO000011 | B12: 45300 | C12: D007 | D12: V014 | E12: BUY016 | F12: Competitive Bid | G12: Closed | H12: Replacement | I12: USD
A13: PO000012 | B13: 45304 | C13: D001 | D13: V016 | E13: BUY008 | F13: Framework Call-off | G13: Closed | H13: Growth | I13: USD
... A1251: PO001250 | B1251: 46231 | C1251: D010 | D1251: V032 | E1251: BUY017 | F1251: Catalog | G1251: Open | H1251: Compliance | I1251: USD

Sheet Fact_PO_Detail
A1: PO_Line_ID | B1: PO_ID | C1: ProductID | D1: VendorID | E1: QuotationID | F1: DepartmentID | G1: PODate | H1: RequestedQty | I1: OrderedQty | J1: BaselineUnitPrice | K1: InitialQuoteUnitPrice | L1: NegotiatedUnitPrice | M1: Currency | N1: ContractType | O1: Priority | P1: BuyerID | Q1: BaselineAmount | R1: POAmount | S1: CostSavingAmount | T1: CostSavingPct
A2: POL0000001 | B2: PO000001 | C2: P0046 | D2: V010 | E2: QT000001 | F2: D004 | G2: 45313 | H2: 30 | I2: 30 | J2: 1403.41 | K2: 1485.89 | L2: 1332.03 | M2: USD | N2: Spot Purchase | O2: Expedited | P2: BUY002 | Q2: =I2*J2 -> 42102.3 | R2: =I2*L2 -> 39960.9 | S2: =Q2-R2 -> 2141.4 | T2: =IF(Q2=0,0,S2/Q2) -> 0.050861829
A3: POL0000002 | B3: PO000003 | C3: P0053 | D3: V041 | E3: QT000002 | F3: D004 | G3: 45321 | H3: 30 | I3: 30 | J3: 856.18 | K3: 862.89 | L3: 776.11 | M3: USD | N3: Spot Purchase | O3: Expedited | P3: BUY002 | Q3: =I3*J3 -> 25685.4 | R3: =I3*L3 -> 23283.3 | S3: =Q3-R3 -> 2402.1 | T3: =IF(Q3=0,0,S3/Q3) -> 0.093520054
A4: POL0000003 | B4: PO000002 | C4: P0003 | D4: V039 | E4: QT000003 | F4: D004 | G4: 45307 | H4: 13 | I4: 13 | J4: 512.96 | K4: 501.73 | L4: 492.76 | M4: USD | N4: Annual Contract | O4: Standard | P4: BUY002 | Q4: =I4*J4 -> 6668.48 | R4: =I4*L4 -> 6405.88 | S4: =Q4-R4 -> 262.6 | T4: =IF(Q4=0,0,S4/Q4) -> 0.039379289
A5: POL0000004 | B5: PO000005 | C5: P0096 | D5: V048 | E5: QT000004 | F5: D005 | G5: 45308 | H5: 29 | I5: 29 | J5: 1837.35 | K5: 1819.58 | L5: 1715.33 | M5: USD | N5: Annual Contract | O5: Expedited | P5: BUY012 | Q5: =I5*J5 -> 53283.15 | R5: =I5*L5 -> 49744.57 | S5: =Q5-R5 -> 3538.58 | T5: =IF(Q5=0,0,S5/Q5) -> 0.066410863
A6: POL0000005 | B6: PO000004 | C6: P0073 | D6: V025 | E6: QT000005 | F6: D005 | G6: 45327 | H6: 20 | I6: 20 | J6: 2243.74 | K6: 2194.48 | L6: 1981.33 | M6: USD | N6: Annual Contract | O6: Standard | P6: BUY012 | Q6: =I6*J6 -> 44874.8 | R6: =I6*L6 -> 39626.6 | S6: =Q6-R6 -> 5248.2 | T6: =IF(Q6=0,0,S6/Q6) -> 0.11695205
A7: POL0000006 | B7: PO000004 | C7: P0061 | D7: V025 | E7: QT000006 | F7: D005 | G7: 45327 | H7: 9 | I7: 9 | J7: 1408.72 | K7: 1389.28 | L7: 1317.4 | M7: USD | N7: Annual Contract | O7: Standard | P7: BUY012 | Q7: =I7*J7 -> 12678.48 | R7: =I7*L7 -> 11856.6 | S7: =Q7-R7 -> 821.88 | T7: =IF(Q7=0,0,S7/Q7) -> 0.064824805
A8: POL0000007 | B8: PO000007 | C8: P0049 | D8: V049 | E8: QT000007 | F8: D001 | G8: 45371 | H8: 39 | I8: 39 | J8: 1850.17 | K8: 1942.34 | L8: 1803.53 | M8: USD | N8: Framework Agreement | O8: Expedited | P8: BUY010 | Q8: =I8*J8 -> 72156.63 | R8: =I8*L8 -> 70337.67 | S8: =Q8-R8 -> 1818.96 | T8: =IF(Q8=0,0,S8/Q8) -> 0.025208494
A9: POL0000008 | B9: PO000006 | C9: P0028 | D9: V040 | E9: QT000008 | F9: D001 | G9: 45300 | H9: 1 | I9: 1 | J9: 2792.88 | K9: 2773.29 | L9: 2674.37 | M9: USD | N9: Annual Contract | O9: Standard | P9: BUY010 | Q9: =I9*J9 -> 2792.88 | R9: =I9*L9 -> 2674.37 | S9: =Q9-R9 -> 118.51 | T9: =IF(Q9=0,0,S9/Q9) -> 0.042432901
A10: POL0000009 | B10: PO000009 | C10: P0106 | D10: V034 | E10: QT000009 | F10: D009 | G10: 45341 | H10: 41 | I10: 41 | J10: 7003.51 | K10: 6933.73 | L10: 6497.16 | M10: USD | N10: Spot Purchase | O10: Standard | P10: BUY002 | Q10: =I10*J10 -> 287143.91 | R10: =I10*L10 -> 266383.56 | S10: =Q10-R10 -> 20760.35 | T10: =IF(Q10=0,0,S10/Q10) -> 0.072299461
A11: POL0000010 | B11: PO000008 | C11: P0093 | D11: V009 | E11: QT000010 | F11: D009 | G11: 45327 | H11: 22 | I11: 22 | J11: 777.16 | K11: 782 | L11: 756.17 | M11: USD | N11: Spot Purchase | O11: Expedited | P11: BUY002 | Q11: =I11*J11 -> 17097.52 | R11: =I11*L11 -> 16635.74 | S11: =Q11-R11 -> 461.78 | T11: =IF(Q11=0,0,S11/Q11) -> 0.027008595
A12: POL0000011 | B12: PO000015 | C12: P0033 | D12: V057 | E12: QT000011 | F12: D008 | G12: 45346 | H12: 43 | I12: 43 | J12: 1356.02 | K12: 1406.92 | L12: 1243.72 | M12: USD | N12: Spot Purchase | O12: Expedited | P12: BUY018 | Q12: =I12*J12 -> 58308.86 | R12: =I12*L12 -> 53479.96 | S12: =Q12-R12 -> 4828.9 | T12: =IF(Q12=0,0,S12/Q12) -> 0.082815888
A13: POL0000012 | B13: PO000009 | C13: P0034 | D13: V034 | E13: QT000012 | F13: D009 | G13: 45341 | H13: 6 | I13: 6 | J13: 1120.04 | K13: 1121.2 | L13: 1011.04 | M13: USD | N13: Annual Contract | O13: Standard | P13: BUY002 | Q13: =I13*J13 -> 6720.24 | R13: =I13*L13 -> 6066.24 | S13: =Q13-R13 -> 654 | T13: =IF(Q13=0,0,S13/Q13) -> 0.097317953
... A3001: POL0003000 | B3001: PO001238 | C3001: P0067 | D3001: V043 | E3001: QT003000 | F3001: D003 | G3001: 46234 | H3001: 22 | I3001: 22 | J3001: 887.67 | K3001: 870.25 | L3001: 842.18 | M3001: USD | N3001: Framework Agreement | O3001: Standard | P3001: BUY003 | Q3001: =I3001*J3001 -> 19528.74 | R3001: =I3001*L3001 -> 18527.96 | S3001: =Q3001-R3001 -> 1000.78 | T3001: =IF(Q3001=0,0,S3001/Q3001) -> 0.051246522

Sheet Fact_Quotation
A1: QuotationID | B1: PO_Line_ID | C1: VendorID | D1: QuotationDate | E1: InitialQuoteUnitPrice | F1: NegotiatedUnitPrice | G1: NegotiationSaving | H1: Currency | I1: QuotationChannel | J1: QuotationStatus
A2: QT000001 | B2: POL0000001 | C2: V010 | D2: 45310 | E2: 1485.89 | F2: 1332.03 | G2: 4615.8 | H2: USD | I2: Email RFQ | J2: Accepted
A3: QT000002 | B3: POL0000002 | C3: V041 | D3: 45317 | E3: 862.89 | F3: 776.11 | G3: 2603.4 | H3: USD | I3: Framework Rate | J3: Accepted
A4: QT000003 | B4: POL0000003 | C4: V039 | D4: 45302 | E4: 501.73 | F4: 492.76 | G4: 116.61 | H4: USD | I4: E-Sourcing | J4: Accepted
A5: QT000004 | B5: POL0000004 | C5: V048 | D5: 45302 | E5: 1819.58 | F5: 1715.33 | G5: 3023.25 | H5: USD | I5: E-Sourcing | J5: Accepted
A6: QT000005 | B6: POL0000005 | C6: V025 | D6: 45320 | E6: 2194.48 | F6: 1981.33 | G6: 4263 | H6: USD | I6: E-Sourcing | J6: Accepted
A7: QT000006 | B7: POL0000006 | C7: V025 | D7: 45319 | E7: 1389.28 | F7: 1317.4 | G7: 646.92 | H7: USD | I7: E-Sourcing | J7: Accepted
A8: QT000007 | B8: POL0000007 | C8: V049 | D8: 45362 | E8: 1942.34 | F8: 1803.53 | G8: 5413.59 | H8: USD | I8: Email RFQ | J8: Accepted
A9: QT000008 | B9: POL0000008 | C9: V040 | D9: 45292 | E9: 2773.29 | F9: 2674.37 | G9: 98.92 | H9: USD | I9: Framework Rate | J9: Accepted
A10: QT000009 | B10: POL0000009 | C10: V034 | D10: 45330 | E10: 6933.73 | F10: 6497.16 | G10: 17899.37 | H10: USD | I10: E-Sourcing | J10: Accepted
A11: QT000010 | B11: POL0000010 | C11: V009 | D11: 45315 | E11: 782 | F11: 756.17 | G11: 568.26 | H11: USD | I11: Email RFQ | J11: Accepted
A12: QT000011 | B12: POL0000011 | C12: V057 | D12: 45333 | E12: 1406.92 | F12: 1243.72 | G12: 7017.6 | H12: USD | I12: E-Sourcing | J12: Accepted
A13: QT000012 | B13: POL0000012 | C13: V034 | D13: 45327 | E13: 1121.2 | F13: 1011.04 | G13: 660.96 | H13: USD | I13: Email RFQ | J13: Accepted
... A3001: QT003000 | B3001: POL0003000 | C3001: V043 | D3001: 46215 | E3001: 870.25 | F3001: 842.18 | G3001: 617.54 | H3001: USD | I3001: Framework Rate | J3001: Accepted

Sheet Fact_Delivery
A1: DeliveryID | B1: PO_Line_ID | C1: ExpectedDeliveryDate | D1: ActualDeliveryDate | E1: DelayDays | F1: DeliveryPerformance | G1: DeliveredQty | H1: RejectedQty | I1: QualityScore
A2: DEL000001 | B2: POL0000001 | C2: 45324 | D2: 45333 | E2: 9 | F2: Late | G2: 30 | H2: 0 | I2: 84.55
A3: DEL000002 | B3: POL0000002 | C3: 45343 | D3: 45342 | E3: 0 | F3: On Time | G3: 30 | H3: 0 | I3: 95.04
A4: DEL000003 | B4: POL0000003 | C4: 45316 | D4: 45314 | E4: 0 | F4: On Time | G4: 13 | H4: 0 | I4: 84
A5: DEL000004 | B5: POL0000004 | C5: 45332 | D5: 45329 | E5: 0 | F5: On Time | G5: 29 | H5: 0 | I5: 92.27
A6: DEL000005 | B6: POL0000005 | C6: 45356 | D6: 45352 | E6: 0 | F6: On Time | G6: 20 | H6: 0 | I6: 98.12
A7: DEL000006 | B7: POL0000006 | C7: 45356 | D7: 45351 | E7: 0 | F7: On Time | G7: 9 | H7: 0 | I7: 93.75
A8: DEL000007 | B8: POL0000007 | C8: 45397 | D8: 45397 | E8: 0 | F8: On Time | G8: 39 | H8: 0 | I8: 97.77
A9: DEL000008 | B9: POL0000008 | C9: 45339 | D9: 45338 | E9: 0 | F9: On Time | G9: 1 | H9: 0 | I9: 86.64
A10: DEL000009 | B10: POL0000009 | C10: 45377 | D10: 45375 | E10: 0 | F10: On Time | G10: 41 | H10: 0 | I10: 99.66
A11: DEL000010 | B11: POL0000010 | C11: 45338 | D11: 45335 | E11: 0 | F11: On Time | G11: 22 | H11: 0 | I11: 92.33
A12: DEL000011 | B12: POL0000011 | C12: 45386 | D12: 45395 | E12: 9 | F12: Late | G12: 43 | H12: 0 | I12: 87.63
A13: DEL000012 | B13: POL0000012 | C13: 45377 | D13: 45378 | E13: 1 | F13: Late | G13: 6 | H13: 0 | I13: 83.53
... A3001: DEL003000 | B3001: POL0003000 | C3001: 46254 | D3001: 46249 | E3001: 0 | F3001: On Time | G3001: 22 | H3001: 0 | I3001: 91.38

Sheet Fact_Invoice
A1: InvoiceID | B1: PO_ID | C1: InvoiceDate | D1: DueDate | E1: InvoiceAmount | F1: DiscrepancyAmount | G1: Currency | H1: ThreeWayMatchStatus
A2: INV000001 | B2: PO000001 | C2: 45336 | D2: 45366 | E2: 309673.78 | F2: 619.35 | G2: USD | H2: Exception
A3: INV000002 | B3: PO000002 | C3: 45324 | D3: 45354 | E3: 16358.43 | F3: 0 | G3: USD | H3: Matched
A4: INV000003 | B4: PO000003 | C4: 45364 | D4: 45409 | E4: 42957.9 | F4: 0 | G4: USD | H4: Matched
A5: INV000004 | B5: PO000004 | C5: 45360 | D5: 45420 | E5: 87211.42 | F5: 0 | G5: USD | H5: Matched
A6: INV000005 | B6: PO000005 | C6: 45348 | D6: 45408 | E6: 214365.33 | F6: 0 | G6: USD | H6: Matched
A7: INV000006 | B7: PO000006 | C7: 45346 | D7: 45391 | E7: 106244.84 | F7: 0 | G7: USD | H7: Matched
A8: INV000007 | B8: PO000007 | C8: 45418 | D8: 45463 | E8: 141761.83 | F8: 0 | G8: USD | H8: Matched
A9: INV000008 | B9: PO000008 | C9: 45345 | D9: 45375 | E9: 31836.1 | F9: 0 | G9: USD | H9: Matched
A10: INV000009 | B10: PO000009 | C10: 45389 | D10: 45419 | E10: 287660.31 | F10: 0 | G10: USD | H10: Matched
A11: INV000010 | B11: PO000010 | C11: 45358 | D11: 45403 | E11: 1593.94 | F11: 0 | G11: USD | H11: Matched
A12: INV000011 | B12: PO000011 | C12: 45359 | D12: 45389 | E12: 75857.6 | F12: 0 | G12: USD | H12: Matched
A13: INV000012 | B13: PO000012 | C13: 45318 | D13: 45348 | E13: 271554.61 | F13: 0 | G13: USD | H13: Matched
... A1251: INV001250 | B1251: PO001250 | C1251: 46259 | D1251: 46289 | E1251: 318260.8 | F1251: 0 | G1251: USD | H1251: Matched

Sheet Fact_Payment
A1: PaymentID | B1: InvoiceID | C1: PaymentDate | D1: PaidAmount | E1: Currency | F1: PaymentStatus | G1: PaymentMethod
A2: PAY000001 | B2: INV000001 | C2: 45367 | D2: 309673.78 | E2: USD | F2: Paid Late | G2: Wire
A3: PAY000002 | B3: INV000002 | C3: 45356 | D3: 16358.43 | E3: USD | F3: Paid Late | G3: Wire
A4: PAY000003 | B4: INV000003 | C4: 45405 | D4: 42957.9 | E4: USD | F4: Paid On Time | G4: Wire
A5: PAY000004 | B5: INV000004 | C5: 45424 | D5: 87211.42 | E5: USD | F5: Paid Late | G5: Wire
A6: PAY000005 | B6: INV000005 | C6: 45413 | D6: 214365.33 | E6: USD | F6: Paid Late | G6: Bank Transfer
A7: PAY000006 | B7: INV000006 | C7: 45384 | D7: 106244.84 | E7: USD | F7: Paid On Time | G7: ACH
A8: PAY000007 | B8: INV000007 | C8: 45455 | D8: 141761.83 | E8: USD | F8: Paid On Time | G8: Wire
A9: PAY000008 | B9: INV000008 | C9: 45383 | D9: 31836.1 | E9: USD | F9: Paid Late | G9: Bank Transfer
A10: PAY000009 | B10: INV000009 | C10: 45428 | D10: 287660.31 | E10: USD | F10: Paid Late | G10: Bank Transfer
A11: PAY000010 | B11: INV000010 | C11: 45392 | D11: 1593.94 | E11: USD | F11: Paid On Time | G11: ACH
A12: PAY000011 | B12: INV000011 | C12: 45400 | D12: 75857.6 | E12: USD | F12: Paid Late | G12: Wire
A13: PAY000012 | B13: INV000012 | C13: 45360 | D13: 271554.61 | E13: USD | F13: Paid Late | G13: Wire
... A18: PAY000017 | B18: INV000017 | C18: 45421 | D18: 88199.52 | E18: USD | F18: Paid On Time | G18: Bank Transfer
A19: PAY000018 | B19: INV000018 | D19: 0 | E19: USD | F19: Overdue | G19: Bank Transfer
A20: PAY000019 | B20: INV000019 | C20: 45429 | D20: 61852.16 | E20: USD | F20: Paid Late | G20: ACH
A21: PAY000020 | B21: INV000020 | C21: 45424 | D21: 42937.97 | E21: USD | F21: Paid Late | G21: Wire
A22: PAY000021 | B22: INV000021 | C22: 45387 | D22: 85914.85 | E22: USD | F22: Paid On Time | G22: Wire
A23: PAY000022 | B23: INV000022 | C23: 45414 | D23: 51967.88 | E23: USD | F23: Paid On Time | G23: Wire
A24: PAY000023 | B24: INV000023 | C24: 45401 | D24: 35270.09 | E24: USD | F24: Paid Late | G24: ACH
A25: PAY000024 | B25: INV000024 | C25: 45396 | D25: 65832.61 | E25: USD | F25: Paid Late | G25: Bank Transfer
A26: PAY000025 | B26: INV000025 | C26: 45373 | D26: 539085.56 | E26: USD | F26: Paid On Time | G26: ACH
A27: PAY000026 | B27: INV000026 | C27: 45442 | D27: 183143.81 | E27: USD | F27: Paid Late | G27: Bank Transfer
A28: PAY000027 | B28: INV000027 | C28: 45356 | D28: 302542.24 | E28: USD | F28: Paid On Time | G28: Bank Transfer
A29: PAY000028 | B29: INV000028 | C29: 45384 | D29: 36823.48 | E29: USD | F29: Paid On Time | G29: Wire
A30: PAY000029 | B30: INV000029 | C30: 45372 | D30: 49241.82 | E30: USD | F30: Paid Late | G30: Wire
A31: PAY000030 | B31: INV000030 | C31: 45461 | D31: 6142.57 | E31: USD | F31: Paid Late | G31: ACH
... A62: PAY000061 | B62: INV000061 | C62: 45426 | D62: 42436.68 | E62: USD | F62: Paid On Time | G62: Bank Transfer
A63: PAY000062 | B63: INV000062 | D63: 0 | E63: USD | F63: Overdue | G63: ACH
A64: PAY000063 | B64: INV000063 | C64: 45455 | D64: 154615.55 | E64: USD | F64: Paid On Time | G64: Bank Transfer
A65: PAY000064 | B65: INV000064 | C65: 45444 | D65: 371653.84 | E65: USD | F65: Paid Late | G65: Wire
A66: PAY000065 | B66: INV000065 | C66: 45442 | D66: 136472.13 | E66: USD | F66: Paid Late | G66: Wire
A67: PAY000066 | B67: INV000066 | C67: 45499 | D67: 53898.08 | E67: USD | F67: Paid Late | G67: Wire
A68: PAY000067 | B68: INV000067 | C68: 45440 | D68: 54250.73 | E68: USD | F68: Paid Late | G68: Bank Transfer
A69: PAY000068 | B69: INV000068 | C69: 45422 | D69: 486766.49 | E69: USD | F69: Paid Late | G69: Wire
A70: PAY000069 | B70: INV000069 | C70: 45423 | D70: 3821.24 | E70: USD | F70: Paid On Time | G70: Bank Transfer
A71: PAY000070 | B71: INV000070 | C71: 45555 | D71: 413660.22 | E71: USD | F71: Paid Late | G71: ACH
A72: PAY000071 | B72: INV000071 | C72: 45454 | D72: 99553.77 | E72: USD | F72: Paid Late | G72: Wire
A73: PAY000072 | B73: INV000072 | C73: 45432 | D73: 54755.06 | E73: USD | F73: Paid On Time | G73: Bank Transfer
A74: PAY000073 | B74: INV000073 | C74: 45501 | D74: 57972.01 | E74: USD | F74: Paid Late | G74: ACH
...

Sheet KPI_Check
A1: PROCUREMENT DATASET V2 — KPI CONTROL CHECK
A4: KPI | B4: Value
A5: Purchase Orders | B5: =COUNTA(Fact_PO_Header!$A$2:$A$1251) -> 1250
A6: PO Line Transactions | B6: =COUNTA(Fact_PO_Detail!$A$2:$A$3001) -> 3000
A7: Total Spend | B7: =SUM(Fact_PO_Detail!$R$2:$R$3001) -> 1.2864151e+08
A8: Baseline Spend | B8: =SUM(Fact_PO_Detail!$Q$2:$Q$3001) -> 1.3847467e+08
A9: Cost Saving | B9: =SUM(Fact_PO_Detail!$S$2:$S$3001) -> 9833158.5
A10: Cost Saving % | B10: =IF(B8=0,0,B9/B8) -> 0.071010522
A11: On-Time Delivery % | B11: =COUNTIF(Fact_Delivery!$F$2:$F$3001,"On Time")/COUNTA(Fact_Delivery!$A$2:$A$3001) -> 0.829
A12: Overdue Invoices | B12: =COUNTIF(Fact_Payment!$F$2:$F$1251,"Overdue") -> 89
A13: Invoice Outstanding | B13: =SUM(Fact_Invoice!$E$2:$E$1251)-SUM(Fact_Payment!$D$2:$D$1251) -> 20079602
A15: SQL KPI | B15: Suggested expression | C15: Business meaning | D15: Power BI measure | E15: Expected use | F15: Notes
A16: Total Spend | B16: SUM(OrderedQty * NegotiatedUnitPrice) | C16: Committed procurement spend | D16: SUMX(Fact_PO_Detail, [OrderedQty]*[NegotiatedUnitPrice]) | E16: KPI card and trend | F16: Use PO line grain
A17: Cost Saving | B17: SUM((BaselineUnitPrice-NegotiatedUnitPrice)*OrderedQty) | C17: Saving against approved baseline | D17: SUMX(...) | E17: KPI and category analysis | F17: Negative values represent cost increase
A18: Saving % | B18: Cost Saving / Baseline Spend | C18: Relative procurement efficiency | D18: DIVIDE([Cost Saving],[Baseline Spend]) | E18: Benchmarking | F18: Do not average row percentages
A19: On-Time Delivery % | B19: On-time lines / delivered lines | C19: Supplier delivery reliability | D19: DIVIDE([On Time],[Deliveries]) | E19: Vendor scorecard | F19: Use Fact_Delivery
A20: Invoice Outstanding | B20: InvoiceAmount - PaidAmount | C20: Unpaid liability | D20: [Invoice Amount]-[Paid Amount] | E20: Finance view | F20: Join invoice to payment

Sheet Data_Dictionary
A1: Table | B1: Column | C1: Data type | D1: Key role | E1: Definition
A2: Dim_Date | B2: DateKey | C2: INTEGER | D2: Primary Key | E2: Calendar key in YYYYMMDD format
A3: Dim_Date | B3: FullDate | C3: DATE | D3: Attribute | E3: Business date
A4: Dim_Date | B4: Year | C4: INTEGER | D4: Attribute | E4: Year for Dim_Date
A5: Dim_Date | B5: Quarter | C5: INTEGER | D5: Attribute | E5: Quarter for Dim_Date
A6: Dim_Date | B6: MonthName | C6: VARCHAR | D6: Attribute | E6: MonthName for Dim_Date
A7: Dim_Date | B7: MonthNumber | C7: INTEGER | D7: Attribute | E7: MonthNumber for Dim_Date
A8: Dim_Date | B8: DayName | C8: VARCHAR | D8: Attribute | E8: DayName for Dim_Date
A9: Dim_Date | B9: IsBusinessDay | C9: INTEGER | D9: Attribute | E9: IsBusinessDay for Dim_Date
A10: Dim_Department | B10: DepartmentID | C10: VARCHAR | D10: Primary Key | E10: Unique identifier
A11: Dim_Department | B11: DepartmentName | C11: VARCHAR | D11: Attribute | E11: Owning department attribute
A12: Dim_Department | B12: BusinessUnit | C12: VARCHAR | D12: Attribute | E12: BusinessUnit for Dim_Department
... A109: Fact_Payment | B109: PaymentMethod | C109: VARCHAR | D109: Attribute | E109: PaymentMethod for Fact_Payment

Sheet Dim_Category
A1: CategoryID | B1: CategoryName | C1: CategoryGroup | D1: SpendType | E1: CategoryManager | F1: Status
A2: CAT01 | B2: Laptops | C2: Computing | D2: Goods | E2: A. Morgan | F2: Active
A3: CAT02 | B3: Desktop Computers | C3: Computing | D3: Goods | E3: B. Chen | F3: Active
A4: CAT03 | B4: Monitors | C4: IT Equipment | D4: Goods | E4: C. Patel | F4: Active
A5: CAT04 | B5: Network Equipment | C5: IT Equipment | D5: Goods | E5: D. Garcia | F5: Active
A6: CAT05 | B6: Business Software | C6: Software | D6: Software | E6: E. Wilson | F6: Active
A7: CAT06 | B7: Office Supplies | C7: Office | D7: Goods | E7: F. Kim | F7: Active
A8: CAT07 | B8: Furniture | C8: Facilities | D8: Goods | E8: G. Taylor | F8: Active
A9: CAT08 | B9: Maintenance Services | C9: Facilities | D9: Services | E9: H. Singh | F9: Active
A10: CAT09 | B10: Consulting Services | C10: Professional Services | D10: Services | E10: I. Brown | F10: Active
A11: CAT10 | B11: Media & Creative | C11: Marketing | D11: Services | E11: J. Martin | F11: Active
A12: CAT11 | B12: Mobile Devices | C12: Telecom | D12: Goods | E12: K. Davis | F12: Active
A13: CAT12 | B13: Freight Services | C13: Logistics | D13: Services | E13: L. Anderson | F13: Active
